[16/Jan/2016 00:08:34] ERROR [django.request:231] Internal Server Error: /zened/
Traceback (most recent call last):
  File "/opt/local/Library/Frameworks/Python.framework/Versions/3.2/lib/python3.2/site-packages/django/core/handlers/base.py", line 111, in get_response
    response = wrapped_callback(request, *callback_args, **callback_kwargs)
  File "/Users/quqinglei/Desktop/web-connect-master/zen/views.py", line 63, in zened
    dict['years_of_learning_buddhism'] = datetime.now().year - int(dic['years2start_learning_buddhism']) + 1
KeyError: 'years2start_learning_buddhism'
[16/Jan/2016 00:09:38] ERROR [django.request:231] Internal Server Error: /zened/
Traceback (most recent call last):
  File "/opt/local/Library/Frameworks/Python.framework/Versions/3.2/lib/python3.2/site-packages/django/core/handlers/base.py", line 111, in get_response
    response = wrapped_callback(request, *callback_args, **callback_kwargs)
  File "/Users/quqinglei/Desktop/web-connect-master/zen/views.py", line 63, in zened
    dict['years_of_learning_buddhism'] = datetime.now().year - int(dic['year2start_learning_buddhism']) + 1
TypeError: 'type' object does not support item assignment
